Workbook

Sheet Dashboard
B2: ANNEX A READINESS DASHBOARD
B3: Ringkasan kesiapan 93 kontrol ISO/IEC 27001:2022
B5: ='Master Data'!C6 | K5: ='Master Data'!C9
B7: TOTAL KONTROL | F7: BELUM DINILAI | J7: SIAP
B8: =COUNTA('Checklist 93 Kontrol'!B7:B99) | F8: =COUNTIFS('Checklist 93 Kontrol'!X7:X99,"Belum dinilai") | J8: =COUNTIFS('Checklist 93 Kontrol'!X7:X99,"Siap")
B10: BERLAKU | F10: PERLU TINDAKAN | J10: KESIAPAN KONTROL BERLAKU
B11: =COUNTIFS('Checklist 93 Kontrol'!G7:G99,"Berlaku") | F11: =COUNTIFS('Checklist 93 Kontrol'!Z7:Z99,"Ya") | J11: =IF(B11=0,"Belum ada data",J8/B11)
B14: =IF(F8=93,"Assessment belum dimulai. Tentukan relevansi setiap kontrol pada Checklist 93 Kontrol.",IF(F11>0,"Masih ada kontrol yang memerlukan tindakan atau review jadwal.",IF(F8>0,"Assessment belum lengkap. Lanjutkan kontrol yang belum dinilai.","Seluruh kontrol telah dinilai tanpa action terbuka. Lanjutkan review substantif auditor.")))
B18: Tema | C18: Total | D18: Relevansi diputuskan | E18: Siap | F18: Perlu tindakan | G18: Kesiapan berlaku
B19: Organizational | C19: 37 | D19: =COUNTIFS('Checklist 93 Kontrol'!C7:C99,B19,'Checklist 93 Kontrol'!G7:G99,"<>Belum ditentukan") | E19: =COUNTIFS('Checklist 93 Kontrol'!C7:C99,B19,'Checklist 93 Kontrol'!X7:X99,"Siap") | F19: =COUNTIFS('Checklist 93 Kontrol'!C7:C99,B19,'Checklist 93 Kontrol'!Z7:Z99,"Ya") | G19: =IF(COUNTIFS('Checklist 93 Kontrol'!C7:C99,B19,'Checklist 93 Kontrol'!G7:G99,"Berlaku")=0,"",E19/COUNTIFS('Checklist 93 Kontrol'!C7:C99,B19,'Checklist 93 Kontrol'!G7:G99,"Berlaku"))
B20: People | C20: 8 | D20: =COUNTIFS('Checklist 93 Kontrol'!C7:C99,B20,'Checklist 93 Kontrol'!G7:G99,"<>Belum ditentukan") | E20: =COUNTIFS('Checklist 93 Kontrol'!C7:C99,B20,'Checklist 93 Kontrol'!X7:X99,"Siap") | F20: =COUNTIFS('Checklist 93 Kontrol'!C7:C99,B20,'Checklist 93 Kontrol'!Z7:Z99,"Ya") | G20: =IF(COUNTIFS('Checklist 93 Kontrol'!C7:C99,B20,'Checklist 93 Kontrol'!G7:G99,"Berlaku")=0,"",E20/COUNTIFS('Checklist 93 Kontrol'!C7:C99,B20,'Checklist 93 Kontrol'!G7:G99,"Berlaku"))
B21: Physical | C21: 14 | D21: =COUNTIFS('Checklist 93 Kontrol'!C7:C99,B21,'Checklist 93 Kontrol'!G7:G99,"<>Belum ditentukan") | E21: =COUNTIFS('Checklist 93 Kontrol'!C7:C99,B21,'Checklist 93 Kontrol'!X7:X99,"Siap") | F21: =COUNTIFS('Checklist 93 Kontrol'!C7:C99,B21,'Checklist 93 Kontrol'!Z7:Z99,"Ya") | G21: =IF(COUNTIFS('Checklist 93 Kontrol'!C7:C99,B21,'Checklist 93 Kontrol'!G7:G99,"Berlaku")=0,"",E21/COUNTIFS('Checklist 93 Kontrol'!C7:C99,B21,'Checklist 93 Kontrol'!G7:G99,"Berlaku"))
B22: Technological | C22: 34 | D22: =COUNTIFS('Checklist 93 Kontrol'!C7:C99,B22,'Checklist 93 Kontrol'!G7:G99,"<>Belum ditentukan") | E22: =COUNTIFS('Checklist 93 Kontrol'!C7:C99,B22,'Checklist 93 Kontrol'!X7:X99,"Siap") | F22: =COUNTIFS('Checklist 93 Kontrol'!C7:C99,B22,'Checklist 93 Kontrol'!Z7:Z99,"Ya") | G22: =IF(COUNTIFS('Checklist 93 Kontrol'!C7:C99,B22,'Checklist 93 Kontrol'!G7:G99,"Berlaku")=0,"",E22/COUNTIFS('Checklist 93 Kontrol'!C7:C99,B22,'Checklist 93 Kontrol'!G7:G99,"Berlaku"))
B26: Status kesiapan
B27: Siap | C27: =COUNTIFS('Checklist 93 Kontrol'!X7:X99,"Siap")
B28: Belum siap | C28: =COUNTIFS('Checklist 93 Kontrol'!X7:X99,"Belum siap")
B29: Dikecualikan | C29: =COUNTIFS('Checklist 93 Kontrol'!X7:X99,"Dikecualikan")
B30: Belum dinilai | C30: =COUNTIFS('Checklist 93 Kontrol'!X7:X99,"Belum dinilai")
B35: Catatan metodologi | C35: Kesiapan % = kontrol berstatus Siap ÷ kontrol yang ditetapkan Berlaku. Kontrol Tidak berlaku tidak masuk penyebut.
B38: Navigasi | C38: Petunjuk → Checklist 93 Kontrol → Review Kesiapan

Sheet Petunjuk
B2: PANDUAN PENGGUNAAN
B3: Cara menggunakan checklist tanpa mengaburkan keputusan SoA dan hasil audit
B6: 01. Isi profil | C6: Lengkapi profil dan tanggal acuan pada Master Data. Tanggal acuan menjadi cut-off indikator deadline.
B8: 02. Tentukan relevansi | C8: Nilai setiap kontrol sebagai Berlaku atau Tidak berlaku berdasarkan risiko, ruang lingkup, dan SoA organisasi.
B10: 03. Catat justifikasi | C10: Untuk Tidak berlaku, tulis alasan yang spesifik. Checklist tidak menggantikan Statement of Applicability resmi.
B12: 04. Nilai implementasi | C12: Untuk kontrol Berlaku, isi implementasi, ketersediaan bukti, desain kontrol, dan efektivitas operasional.
B14: 05. Hubungkan bukti | C14: Gunakan Evidence ID atau tautan restricted-access agar kontrol dapat ditelusuri ke Master Audit Evidence Index.
B16: 06. Validasi | C16: Isi reviewer dan tanggal validasi. Status Siap hanya muncul bila penerapan dan bukti memenuhi seluruh gate.
B18: 07. Jadwalkan review | C18: Isi Review berikutnya, termasuk untuk kontrol Tidak berlaku agar keputusan relevansi ditinjau ulang.
B20: 08. Tindak lanjuti gap | C20: Isi catatan, tindakan, prioritas, PIC, dan target. Gunakan Review Kesiapan untuk menyaring action terbuka.
B22: Sel krem | C22: Input pengguna. Sel biru muda adalah formula. Kolom identitas kontrol berwarna netral dan tidak perlu diedit.
B24: Status Siap | C24: Pemeriksaan kelengkapan internal, bukan opini auditor atau jaminan lulus sertifikasi.
B26: Kontrol Tidak berlaku | C26: Baru dianggap Dikecualikan bila justifikasi, reviewer, dan tanggal validasi lengkap.
B28: Keamanan informasi | C28: Jangan tempel password, token, private key, atau data sensitif. Gunakan tautan dengan akses minimum.
B30: Referensi standar | C30: Gunakan bersama ISO/IEC 27001:2022 berlisensi. Ringkasan kontrol dibuat untuk workflow, bukan pengganti teks standar.

Sheet Checklist 93 Kontrol
B2: CHECKLIST KESIAPAN BUKTI — 93 KONTROL ANNEX A
B3: ISO/IEC 27001:2022 — isi sel krem; hasil otomatis tampil pada kolom biru muda
B6: Kontrol | C6: Tema | D6: Judul kontrol | E6: Fokus pemeriksaan | F6: Contoh bukti objektif | G6: Relevansi SoA | H6: Justifikasi relevansi | I6: Status implementasi | J6: Ketersediaan bukti | K6: Evidence ID / URL | L6: PIC | M6: Review terakhir | N6: Review berikutnya | O6: Desain kontrol | P6: Efektivitas operasional | Q6: Catatan / gap | R6: Tindakan perbaikan | S6: Prioritas | T6: Target | U6: Reviewer | V6: Tanggal validasi | W6: Pemeriksaan field | X6: Kesiapan | Y6: Deadline | Z6: Perlu tindakan
B7: A.5.1 | C7: Organizational | D7: Kebijakan keamanan informasi | E7: Kebijakan disetujui, dikomunikasikan, dan ditinjau berkala | F7: Kebijakan, approval, riwayat versi, bukti sosialisasi | G7: Berlaku | H7: Kontrol A.5.1 relevan dan wajib diterapkan pada platform operasional auditsphere.app. | I7: Diterapkan | J7: Lengkap | K7: DOC-ISO-AS-001 | L7: Lead Information Security | M7: 46302 | N7: 46477 | O7: Memadai | P7: Efektif | Q7: Kebijakan keamanan informasi disahkan Manajemen Puncak mencakup seluruh domain sistem AuditSphere. | R7: Pertahankan efektivitas kontrol dan lakukan review operasional berkala | S7: Sedang | T7: 46477 | U7: Dimas (Group Vision) | V7: 46302 | W7: =IF(G7="Belum ditentukan","Tentukan relevansi",IF(G7="Tidak berlaku",IF(OR(H7="",U7="",V7=""),"Lengkapi justifikasi","Tercatat"),IF(OR(J7="",L7="",N7="",O7="",P7=""),"Lengkapi assessment",IF(AND(I7="Diterapkan",J7="Lengkap",O7="Memadai",P7="Efektif",OR(K7="",U7="",V7="")),"Lengkapi bukti/reviewer","Tercatat")))) | X7: =IF(G7="Belum ditentukan","Belum dinilai",IF(G7="Tidak berlaku",IF(W7="Tercatat","Dikecualikan","Belum siap"),IF(AND(I7="Diterapkan",J7="Lengkap",O7="Memadai",P7="Efektif",W7="Tercatat"),"Siap","Belum siap"))) | Y7: =IF(G7="Belum ditentukan","Belum dijadwalkan",IF(N7="","Tanpa jadwal",IF(N7<'Master Data'!$C$9,"Review lewat","Dalam jadwal"))) | Z7: =IF(X7="Belum dinilai","Belum dinilai",IF(AND(OR(X7="Siap",X7="Dikecualikan"),Y7="Dalam jadwal"),"Tidak","Ya"))
B8: A.5.2 | C8: Organizational | D8: Peran dan tanggung jawab keamanan informasi | E8: Peran, kewenangan, dan akuntabilitas keamanan ditetapkan | F8: RACI, job description, surat penunjukan, struktur organisasi | G8: Berlaku | H8: Kontrol A.5.2 relevan dan wajib diterapkan pada platform operasional auditsphere.app. | I8: Diterapkan | J8: Lengkap | K8: DOC-ISO-AS-001-Sec14-RACI | L8: Tech Lead AIFL | M8: 46302 | N8: 46477 | O8: Memadai | P8: Efektif | Q8: Matriks RACI formal menetapkan penanggung jawab development, infrastructure, security, dan QA. | R8: Pertahankan efektivitas kontrol dan lakukan review operasional berkala | S8: Sedang | T8: 46477 | U8: Dimas (Group Vision) | V8: 46302 | W8: =IF(G8="Belum ditentukan","Tentukan relevansi",IF(G8="Tidak berlaku",IF(OR(H8="",U8="",V8=""),"Lengkapi justifikasi","Tercatat"),IF(OR(J8="",L8="",N8="",O8="",P8=""),"Lengkapi assessment",IF(AND(I8="Diterapkan",J8="Lengkap",O8="Memadai",P8="Efektif",OR(K8="",U8="",V8="")),"Lengkapi bukti/reviewer","Tercatat")))) | X8: =IF(G8="Belum ditentukan","Belum dinilai",IF(G8="Tidak berlaku",IF(W8="Tercatat","Dikecualikan","Belum siap"),IF(AND(I8="Diterapkan",J8="Lengkap",O8="Memadai",P8="Efektif",W8="Tercatat"),"Siap","Belum siap"))) | Y8: =IF(G8="Belum ditentukan","Belum dijadwalkan",IF(N8="","Tanpa jadwal",IF(N8<'Master Data'!$C$9,"Review lewat","Dalam jadwal"))) | Z8: =IF(X8="Belum dinilai","Belum dinilai",IF(AND(OR(X8="Siap",X8="Dikecualikan"),Y8="Dalam jadwal"),"Tidak","Ya"))
B9: A.5.3 | C9: Organizational | D9: Pemisahan tugas | E9: Tugas yang berpotensi konflik dipisahkan atau dikompensasi | F9: Matriks SoD, approval workflow, daftar konflik dan kompensasi | G9: Berlaku | H9: Kontrol A.5.3 relevan dan wajib diterapkan pada platform operasional auditsphere.app. | I9: Diterapkan | J9: Lengkap | K9: SRC-backend/auth-service/models/user.go | L9: Engineering Lead | M9: 46302 | N9: 46477 | O9: Memadai | P9: Efektif | Q9: Pemisahan wewenang RBAC 5-level: CAE, Lead Auditor, Auditor, Reviewer, dan Administrator. | R9: Pertahankan efektivitas kontrol dan lakukan review operasional berkala | S9: Sedang | T9: 46477 | U9: Dimas (Group Vision) | V9: 46302 | W9: =IF(G9="Belum ditentukan","Tentukan relevansi",IF(G9="Tidak berlaku",IF(OR(H9="",U9="",V9=""),"Lengkapi justifikasi","Tercatat"),IF(OR(J9="",L9="",N9="",O9="",P9=""),"Lengkapi assessment",IF(AND(I9="Diterapkan",J9="Lengkap",O9="Memadai",P9="Efektif",OR(K9="",U9="",V9="")),"Lengkapi bukti/reviewer","Tercatat")))) | X9: =IF(G9="Belum ditentukan","Belum dinilai",IF(G9="Tidak berlaku",IF(W9="Tercatat","Dikecualikan","Belum siap"),IF(AND(I9="Diterapkan",J9="Lengkap",O9="Memadai",P9="Efektif",W9="Tercatat"),"Siap","Belum siap"))) | Y9: =IF(G9="Belum ditentukan","Belum dijadwalkan",IF(N9="","Tanpa jadwal",IF(N9<'Master Data'!$C$9,"Review lewat","Dalam jadwal"))) | Z9: =IF(X9="Belum dinilai","Belum dinilai",IF(AND(OR(X9="Siap",X9="Dikecualikan"),Y9="Dalam jadwal"),"Tidak","Ya"))
B10: A.5.4 | C10: Organizational | D10: Tanggung jawab manajemen | E10: Manajemen memastikan personel mengikuti aturan keamanan | F10: Arahan manajemen, acknowledgement, notulen, bukti monitoring | G10: Berlaku | H10: Kontrol A.5.4 relevan dan wajib diterapkan pada platform operasional auditsphere.app. | I10: Diterapkan | J10: Lengkap | K10: DOC-ISO-AS-001-Sec1.1 | L10: Dimas (Group Vision) | M10: 46302 | N10: 46477 | O10: Memadai | P10: Efektif | Q10: Pimpinan secara aktif mengesahkan kebijakan, sasaran mutu keamanan, dan alokasi sumber daya. | R10: Pertahankan efektivitas kontrol dan lakukan review operasional berkala | S10: Sedang | T10: 46477 | U10: Dimas (Group Vision) | V10: 46302 | W10: =IF(G10="Belum ditentukan","Tentukan relevansi",IF(G10="Tidak berlaku",IF(OR(H10="",U10="",V10=""),"Lengkapi justifikasi","Tercatat"),IF(OR(J10="",L10="",N10="",O10="",P10=""),"Lengkapi assessment",IF(AND(I10="Diterapkan",J10="Lengkap",O10="Memadai",P10="Efektif",OR(K10="",U10="",V10="")),"Lengkapi bukti/reviewer","Tercatat")))) | X10: =IF(G10="Belum ditentukan","Belum dinilai",IF(G10="Tidak berlaku",IF(W10="Tercatat","Dikecualikan","Belum siap"),IF(AND(I10="Diterapkan",J10="Lengkap",O10="Memadai",P10="Efektif",W10="Tercatat"),"Siap","Belum siap"))) | Y10: =IF(G10="Belum ditentukan","Belum dijadwalkan",IF(N10="","Tanpa jadwal",IF(N10<'Master Data'!$C$9,"Review lewat","Dalam jadwal"))) | Z10: =IF(X10="Belum dinilai","Belum dinilai",IF(AND(OR(X10="Siap",X10="Dikecualikan"),Y10="Dalam jadwal"),"Tidak","Ya"))
B11: A.5.5 | C11: Organizational | D11: Kontak dengan pihak berwenang | E11: Kontak otoritas relevan tersedia dan prosedur eskalasi jelas | F11: Daftar kontak, prosedur pelaporan, bukti komunikasi atau uji | G11: Berlaku | H11: Kontrol A.5.5 relevan dan wajib diterapkan pada platform operasional auditsphere.app. | I11: Diterapkan | J11: Lengkap | K11: DOC-ISO-AS-001-Sec11.2 | L11: Legal Counsel | M11: 46302 | N11: 46477 | O11: Memadai | P11: Efektif | Q11: Prosedur komunikasi eskalasi ke regulator dan otoritas hukum (BSSN/Kominfo) terdokumentasi. | R11: Pertahankan efektivitas kontrol dan lakukan review operasional berkala | S11: Sedang | T11: 46477 | U11: Dimas (Group Vision) | V11: 46302 | W11: =IF(G11="Belum ditentukan","Tentukan relevansi",IF(G11="Tidak berlaku",IF(OR(H11="",U11="",V11=""),"Lengkapi justifikasi","Tercatat"),IF(OR(J11="",L11="",N11="",O11="",P11=""),"Lengkapi assessment",IF(AND(I11="Diterapkan",J11="Lengkap",O11="Memadai",P11="Efektif",OR(K11="",U11="",V11="")),"Lengkapi bukti/reviewer","Tercatat")))) | X11: =IF(G11="Belum ditentukan","Belum dinilai",IF(G11="Tidak berlaku",IF(W11="Tercatat","Dikecualikan","Belum siap"),IF(AND(I11="Diterapkan",J11="Lengkap",O11="Memadai",P11="Efektif",W11="Tercatat"),"Siap","Belum siap"))) | Y11: =IF(G11="Belum ditentukan","Belum dijadwalkan",IF(N11="","Tanpa jadwal",IF(N11<'Master Data'!$C$9,"Review lewat","Dalam jadwal"))) | Z11: =IF(X11="Belum dinilai","Belum dinilai",IF(AND(OR(X11="Siap",X11="Dikecualikan"),Y11="Dalam jadwal"),"Tidak","Ya"))
B12: A.5.6 | C12: Organizational | D12: Kontak dengan kelompok minat khusus | E12: Organisasi memelihara sumber informasi dan komunitas keamanan relevan | F12: Daftar keanggotaan, mailing list, notulen forum, advisory | G12: Berlaku | H12: Penting untuk memperbarui informasi ancaman siber dan tren regulasi audit sektor keuangan terkini. | L12: Security Officer | M12: 46302 | N12: 46418 | Q12: Organisasi belum terdaftar resmi sebagai anggota forum keamanan khusus (seperti Fin-CSIRT atau ISAC sektor finansial). | R12: Rekomendasi: Daftarkan tim keamanan ke komunitas CSIRT/ISAC sektor finansial dan asosiasi profesional (ISACA / IIA Chapter Indonesia) untuk pertukaran intelijen ancaman siber berkala. | S12: Rendah | T12: 46418 | W12: =IF(G12="Belum ditentukan","Tentukan relevansi",IF(G12="Tidak berlaku",IF(OR(H12="",U12="",V12=""),"Lengkapi justifikasi","Tercatat"),IF(OR(J12="",L12="",N12="",O12="",P12=""),"Lengkapi assessment",IF(AND(I12="Diterapkan",J12="Lengkap",O12="Memadai",P12="Efektif",OR(K12="",U12="",V12="")),"Lengkapi bukti/reviewer","Tercatat")))) | X12: =IF(G12="Belum ditentukan","Belum dinilai",IF(G12="Tidak berlaku",IF(W12="Tercatat","Dikecualikan","Belum siap"),IF(AND(I12="Diterapkan",J12="Lengkap",O12="Memadai",P12="Efektif",W12="Tercatat"),"Siap","Belum siap"))) | Y12: =IF(G12="Belum ditentukan","Belum dijadwalkan",IF(N12="","Tanpa jadwal",IF(N12<'Master Data'!$C$9,"Review lewat","Dalam jadwal"))) | Z12: =IF(X12="Belum dinilai","Belum dinilai",IF(AND(OR(X12="Siap",X12="Dikecualikan"),Y12="Dalam jadwal"),"Tidak","Ya"))
B13: A.5.7 | C13: Organizational | D13: Intelijen ancaman | E13: Ancaman dikumpulkan, dianalisis, dan digunakan untuk tindakan | F13: Threat feed, laporan analisis, tiket mitigasi, briefing risiko | G13: Berlaku | H13: Dibutuhkan untuk mengidentifikasi ancaman spesifik pada sistem RBIA (exfiltration, auth bypass, fraud). | L13: SOC Lead | M13: 46302 | N13: 46387 | Q13: Dokumen TIP-001 tersedia, namun automated feed CTI (BSSN/OpenCTI) ke firewall perimeter belum diintegrasikan. | R13: Rekomendasi: Integrasikan feed IoC otomatis (OpenCTI / AlienVault OTX) ke Kong WAF/firewall dan jadwalkan evaluasi false-positive rate berkala. | S13: Sedang | T13: 46387 | W13: =IF(G13="Belum ditentukan","Tentukan relevansi",IF(G13="Tidak berlaku",IF(OR(H13="",U13="",V13=""),"Lengkapi justifikasi","Tercatat"),IF(OR(J13="",L13="",N13="",O13="",P13=""),"Lengkapi assessment",IF(AND(I13="Diterapkan",J13="Lengkap",O13="Memadai",P13="Efektif",OR(K13="",U13="",V13="")),"Lengkapi bukti/reviewer","Tercatat")))) | X13: =IF(G13="Belum ditentukan","Belum dinilai",IF(G13="Tidak berlaku",IF(W13="Tercatat","Dikecualikan","Belum siap"),IF(AND(I13="Diterapkan",J13="Lengkap",O13="Memadai",P13="Efektif",W13="Tercatat"),"Siap","Belum siap"))) | Y13: =IF(G13="Belum ditentukan","Belum dijadwalkan",IF(N13="","Tanpa jadwal",IF(N13<'Master Data'!$C$9,"Review lewat","Dalam jadwal"))) | Z13: =IF(X13="Belum dinilai","Belum dinilai",IF(AND(OR(X13="Siap",X13="Dikecualikan"),Y13="Dalam jadwal"),"Tidak","Ya"))
B14: A.5.8 | C14: Organizational | D14: Keamanan informasi dalam manajemen proyek | E14: Risiko keamanan terintegrasi pada seluruh siklus proyek | F14: Template proyek, risk register, gate review, security sign-off | G14: Berlaku | H14: Kontrol A.5.8 relevan dan wajib diterapkan pada platform operasional auditsphere.app. | I14: Diterapkan | J14: Lengkap | K14: DOC-TMT-001_Threat_Modeling | L14: Security Architect | M14: 46302 | N14: 46477 | O14: Memadai | P14: Efektif | Q14: Penilaian risiko keamanan terintegrasi pada fase perancangan sistem dan sprint rilis. | R14: Pertahankan efektivitas kontrol dan lakukan review operasional berkala | S14: Sedang | T14: 46477 | U14: Dimas (Group Vision) | V14: 46302 | W14: =IF(G14="Belum ditentukan","Tentukan relevansi",IF(G14="Tidak berlaku",IF(OR(H14="",U14="",V14=""),"Lengkapi justifikasi","Tercatat"),IF(OR(J14="",L14="",N14="",O14="",P14=""),"Lengkapi assessment",IF(AND(I14="Diterapkan",J14="Lengkap",O14="Memadai",P14="Efektif",OR(K14="",U14="",V14="")),"Lengkapi bukti/reviewer","Tercatat")))) | X14: =IF(G14="Belum ditentukan","Belum dinilai",IF(G14="Tidak berlaku",IF(W14="Tercatat","Dikecualikan","Belum siap"),IF(AND(I14="Diterapkan",J14="Lengkap",O14="Memadai",P14="Efektif",W14="Tercatat"),"Siap","Belum siap"))) | Y14: =IF(G14="Belum ditentukan","Belum dijadwalkan",IF(N14="","Tanpa jadwal",IF(N14<'Master Data'!$C$9,"Review lewat","Dalam jadwal"))) | Z14: =IF(X14="Belum dinilai","Belum dinilai",IF(AND(OR(X14="Siap",X14="Dikecualikan"),Y14="Dalam jadwal"),"Tidak","Ya"))
B15: A.5.9 | C15: Organizational | D15: Inventaris informasi dan aset terkait | E15: Aset memiliki pemilik, klasifikasi, lokasi, dan status terkini | F15: Asset register, CMDB, daftar pemilik, hasil rekonsiliasi | G15: Berlaku | H15: Kontrol A.5.9 relevan dan wajib diterapkan pada platform operasional auditsphere.app. | I15: Diterapkan | J15: Lengkap | K15: DOC-ISO-AS-001-Sec4.2 | L15: Lead Information Security | M15: 46302 | N15: 46477 | O15: Memadai | P15: Efektif | Q15: Inventarisasi aset informasi (source code, database, evidence, kredensial) tercatat lengkap. | R15: Pertahankan efektivitas kontrol dan lakukan review operasional berkala | S15: Sedang | T15: 46477 | U15: Dimas (Group Vision) | V15: 46302 | W15: =IF(G15="Belum ditentukan","Tentukan relevansi",IF(G15="Tidak berlaku",IF(OR(H15="",U15="",V15=""),"Lengkapi justifikasi","Tercatat"),IF(OR(J15="",L15="",N15="",O15="",P15=""),"Lengkapi assessment",IF(AND(I15="Diterapkan",J15="Lengkap",O15="Memadai",P15="Efektif",OR(K15="",U15="",V15="")),"Lengkapi bukti/reviewer","Tercatat")))) | X15: =IF(G15="Belum ditentukan","Belum dinilai",IF(G15="Tidak berlaku",IF(W15="Tercatat","Dikecualikan","Belum siap"),IF(AND(I15="Diterapkan",J15="Lengkap",O15="Memadai",P15="Efektif",W15="Tercatat"),"Siap","Belum siap"))) | Y15: =IF(G15="Belum ditentukan","Belum dijadwalkan",IF(N15="","Tanpa jadwal",IF(N15<'Master Data'!$C$9,"Review lewat","Dalam jadwal"))) | Z15: =IF(X15="Belum dinilai","Belum dinilai",IF(AND(OR(X15="Siap",X15="Dikecualikan"),Y15="Dalam jadwal"),"Tidak","Ya"))
B16: A.5.10 | C16: Organizational | D16: Penggunaan yang dapat diterima | E16: Aturan penggunaan aset dan informasi ditetapkan dan dipahami | F16: Acceptable use policy, acknowledgement, bukti sosialisasi | G16: Berlaku | H16: Kontrol A.5.10 relevan dan wajib diterapkan pada platform operasional auditsphere.app. | I16: Diterapkan | J16: Lengkap | K16: DOC-AIP-001_AI_Usage_Policy | L16: Security Officer | M16: 46302 | N16: 46477 | O16: Memadai | P16: Efektif | Q16: Pedoman penggunaan aset komputasi dan pemanfaatan AI yang diizinkan dan dilarang disahkan. | R16: Pertahankan efektivitas kontrol dan lakukan review operasional berkala | S16: Sedang | T16: 46477 | U16: Dimas (Group Vision) | V16: 46302 | W16: =IF(G16="Belum ditentukan","Tentukan relevansi",IF(G16="Tidak berlaku",IF(OR(H16="",U16="",V16=""),"Lengkapi justifikasi","Tercatat"),IF(OR(J16="",L16="",N16="",O16="",P16=""),"Lengkapi assessment",IF(AND(I16="Diterapkan",J16="Lengkap",O16="Memadai",P16="Efektif",OR(K16="",U16="",V16="")),"Lengkapi bukti/reviewer","Tercatat")))) | X16: =IF(G16="Belum ditentukan","Belum dinilai",IF(G16="Tidak berlaku",IF(W16="Tercatat","Dikecualikan","Belum siap"),IF(AND(I16="Diterapkan",J16="Lengkap",O16="Memadai",P16="Efektif",W16="Tercatat"),"Siap","Belum siap"))) | Y16: =IF(G16="Belum ditentukan","Belum dijadwalkan",IF(N16="","Tanpa jadwal",IF(N16<'Master Data'!$C$9,"Review lewat","Dalam jadwal"))) | Z16: =IF(X16="Belum dinilai","Belum dinilai",IF(AND(OR(X16="Siap",X16="Dikecualikan"),Y16="Dalam jadwal"),"Tidak","Ya"))
B17: A.5.11 | C17: Organizational | D17: Pengembalian aset | E17: Aset dikembalikan saat perubahan atau akhir hubungan kerja | F17: Offboarding checklist, BA pengembalian, tiket deaktivasi | G17: Berlaku | H17: Mencegah kebocoran data saat karyawan atau pengembang mengakhiri masa penugasan. | L17: HR / Operations Lead | M17: 46302 | N17: 46356 | Q17: Formulir checklist serah terima aset IT dan pencabutan hak akses terpadu dengan HR belum dibakukan. | R17: Rekomendasi: Susun SOP HR-Offboarding Checklist resmi yang mewajibkan penyerahan laptop, token 2FA, dan verifikasi pencabutan akses sebelum rilis surat keluar. | S17: Sedang | T17: 46356 | W17: =IF(G17="Belum ditentukan","Tentukan relevansi",IF(G17="Tidak berlaku",IF(OR(H17="",U17="",V17=""),"Lengkapi justifikasi","Tercatat"),IF(OR(J17="",L17="",N17="",O17="",P17=""),"Lengkapi assessment",IF(AND(I17="Diterapkan",J17="Lengkap",O17="Memadai",P17="Efektif",OR(K17="",U17="",V17="")),"Lengkapi bukti/reviewer","Tercatat")))) | X17: =IF(G17="Belum ditentukan","Belum dinilai",IF(G17="Tidak berlaku",IF(W17="Tercatat","Dikecualikan","Belum siap"),IF(AND(I17="Diterapkan",J17="Lengkap",O17="Memadai",P17="Efektif",W17="Tercatat"),"Siap","Belum siap"))) | Y17: =IF(G17="Belum ditentukan","Belum dijadwalkan",IF(N17="","Tanpa jadwal",IF(N17<'Master Data'!$C$9,"Review lewat","Dalam jadwal"))) | Z17: =IF(X17="Belum dinilai","Belum dinilai",IF(AND(OR(X17="Siap",X17="Dikecualikan"),Y17="Dalam jadwal"),"Tidak","Ya"))
B18: A.5.12 | C18: Organizational | D18: Klasifikasi informasi | E18: Informasi diklasifikasikan sesuai risiko dan kebutuhan bisnis | F18: Skema klasifikasi, inventaris informasi, sampel klasifikasi | G18: Berlaku | H18: Kontrol A.5.12 relevan dan wajib diterapkan pada platform operasional auditsphere.app. | I18: Diterapkan | J18: Lengkap | K18: DOC-ISO-AS-001-Sec4.2 | L18: Compliance Lead | M18: 46302 | N18: 46477 | O18: Memadai | P18: Efektif | Q18: Klasifikasi informasi 4 tingkat (Public, Internal, Confidential, Restricted) diterapkan pada sistem. | R18: Pertahankan efektivitas kontrol dan lakukan review operasional berkala | S18: Sedang | T18: 46477 | U18: Dimas (Group Vision) | V18: 46302 | W18: =IF(G18="Belum ditentukan","Tentukan relevansi",IF(G18="Tidak berlaku",IF(OR(H18="",U18="",V18=""),"Lengkapi justifikasi","Tercatat"),IF(OR(J18="",L18="",N18="",O18="",P18=""),"Lengkapi assessment",IF(AND(I18="Diterapkan",J18="Lengkap",O18="Memadai",P18="Efektif",OR(K18="",U18="",V18="")),"Lengkapi bukti/reviewer","Tercatat")))) | X18: =IF(G18="Belum ditentukan","Belum dinilai",IF(G18="Tidak berlaku",IF(W18="Tercatat","Dikecualikan","Belum siap"),IF(AND(I18="Diterapkan",J18="Lengkap",O18="Memadai",P18="Efektif",W18="Tercatat"),"Siap","Belum siap"))) | Y18: =IF(G18="Belum ditentukan","Belum dijadwalkan",IF(N18="","Tanpa jadwal",IF(N18<'Master Data'!$C$9,"Review lewat","Dalam jadwal"))) | Z18: =IF(X18="Belum dinilai","Belum dinilai",IF(AND(OR(X18="Siap",X18="Dikecualikan"),Y18="Dalam jadwal"),"Tidak","Ya"))
B19: A.5.13 | C19: Organizational | D19: Pelabelan informasi | E19: Label konsisten dengan skema klasifikasi dan media | F19: Prosedur label, sampel dokumen/email, konfigurasi DLP | G19: Berlaku | H19: Kontrol A.5.13 relevan dan wajib diterapkan pada platform operasional auditsphere.app. | I19: Diterapkan | J19: Lengkap | K19: SRC-frontend/pages/audit-result-reports | L19: Lead Developer | M19: 46302 | N19: 46477 | O19: Memadai | P19: Efektif | Q19: Dynamic watermark berisi identitas pengguna dan timestamp diterapkan pada dokumen unduhan audit. | R19: Pertahankan efektivitas kontrol dan lakukan review operasional berkala | S19: Sedang | T19: 46477 | U19: Dimas (Group Vision) | V19: 46302 | W19: =IF(G19="Belum ditentukan","Tentukan relevansi",IF(G19="Tidak berlaku",IF(OR(H19="",U19="",V19=""),"Lengkapi justifikasi","Tercatat"),IF(OR(J19="",L19="",N19="",O19="",P19=""),"Lengkapi assessment",IF(AND(I19="Diterapkan",J19="Lengkap",O19="Memadai",P19="Efektif",OR(K19="",U19="",V19="")),"Lengkapi bukti/reviewer","Tercatat")))) | X19: =IF(G19="Belum ditentukan","Belum dinilai",IF(G19="Tidak berlaku",IF(W19="Tercatat","Dikecualikan","Belum siap"),IF(AND(I19="Diterapkan",J19="Lengkap",O19="Memadai",P19="Efektif",W19="Tercatat"),"Siap","Belum siap"))) | Y19: =IF(G19="Belum ditentukan","Belum dijadwalkan",IF(N19="","Tanpa jadwal",IF(N19<'Master Data'!$C$9,"Review lewat","Dalam jadwal"))) | Z19: =IF(X19="Belum dinilai","Belum dinilai",IF(AND(OR(X19="Siap",X19="Dikecualikan"),Y19="Dalam jadwal"),"Tidak","Ya"))
B20: A.5.14 | C20: Organizational | D20: Transfer informasi | E20: Transfer internal dan eksternal memiliki aturan dan perlindungan | F20: Prosedur transfer, NDA, konfigurasi enkripsi, transfer log | G20: Berlaku | H20: Kontrol A.5.14 relevan dan wajib diterapkan pada platform operasional auditsphere.app. | I20: Diterapkan | J20: Lengkap | K20: TEC-Kong-TLS1.3-Config | L20: DevOps Lead | M20: 46302 | N20: 46477 | O20: Memadai | P20: Efektif | Q20: Enkripsi data in-transit TLS 1.3 ditegakkan pada seluruh rute API publik auditsphere.app. | R20: Pertahankan efektivitas kontrol dan lakukan review operasional berkala | S20: Sedang | T20: 46477 | U20: Dimas (Group Vision) | V20: 46302 | W20: =IF(G20="Belum ditentukan","Tentukan relevansi",IF(G20="Tidak berlaku",IF(OR(H20="",U20="",V20=""),"Lengkapi justifikasi","Tercatat"),IF(OR(J20="",L20="",N20="",O20="",P20=""),"Lengkapi assessment",IF(AND(I20="Diterapkan",J20="Lengkap",O20="Memadai",P20="Efektif",OR(K20="",U20="",V20="")),"Lengkapi bukti/reviewer","Tercatat")))) | X20: =IF(G20="Belum ditentukan","Belum dinilai",IF(G20="Tidak berlaku",IF(W20="Tercatat","Dikecualikan","Belum siap"),IF(AND(I20="Diterapkan",J20="Lengkap",O20="Memadai",P20="Efektif",W20="Tercatat"),"Siap","Belum siap"))) | Y20: =IF(G20="Belum ditentukan","Belum dijadwalkan",IF(N20="","Tanpa jadwal",IF(N20<'Master Data'!$C$9,"Review lewat","Dalam jadwal"))) | Z20: =IF(X20="Belum dinilai","Belum dinilai",IF(AND(OR(X20="Siap",X20="Dikecualikan"),Y20="Dalam jadwal"),"Tidak","Ya"))
B21: A.5.15 | C21: Organizational | D21: Pengendalian akses | E21: Aturan akses berbasis kebutuhan bisnis dan least privilege | F21: Access control policy, matriks akses, hasil review akses | G21: Berlaku | H21: Kontrol A.5.15 relevan dan wajib diterapkan pada platform operasional auditsphere.app. | I21: Diterapkan | J21: Lengkap | K21: SRC-backend/auth-service/pkg/middleware/auth.go | L21: Engineering Lead | M21: 46302 | N21: 46477 | O21: Memadai | P21: Efektif | Q21: Pengendalian akses least-privilege diterapkan pada middleware otorisasi backend Go. | R21: Pertahankan efektivitas kontrol dan lakukan review operasional berkala | S21: Sedang | T21: 46477 | U21: Dimas (Group Vision) | V21: 46302 | W21: =IF(G21="Belum ditentukan","Tentukan relevansi",IF(G21="Tidak berlaku",IF(OR(H21="",U21="",V21=""),"Lengkapi justifikasi","Tercatat"),IF(OR(J21="",L21="",N21="",O21="",P21=""),"Lengkapi assessment",IF(AND(I21="Diterapkan",J21="Lengkap",O21="Memadai",P21="Efektif",OR(K21="",U21="",V21="")),"Lengkapi bukti/reviewer","Tercatat")))) | X21: =IF(G21="Belum ditentukan","Belum dinilai",IF(G21="Tidak berlaku",IF(W21="Tercatat","Dikecualikan","Belum siap"),IF(AND(I21="Diterapkan",J21="Lengkap",O21="Memadai",P21="Efektif",W21="Tercatat"),"Siap","Belum siap"))) | Y21: =IF(G21="Belum ditentukan","Belum dijadwalkan",IF(N21="","Tanpa jadwal",IF(N21<'Master Data'!$C$9,"Review lewat","Dalam jadwal"))) | Z21: =IF(X21="Belum dinilai","Belum dinilai",IF(AND(OR(X21="Siap",X21="Dikecualikan"),Y21="Dalam jadwal"),"Tidak","Ya"))
B22: A.5.16 | C22: Organizational | D22: Manajemen identitas | E22: Siklus hidup identitas dikelola dari pembuatan hingga penghapusan | F22: Prosedur IAM, joiner-mover-leaver log, daftar akun | G22: Berlaku | H22: Kontrol A.5.16 relevan dan wajib diterapkan pada platform operasional auditsphere.app. | I22: Diterapkan | J22: Lengkap | K22: SRC-backend/auth-service/services/user | L22: Engineering Lead | M22: 46302 | N22: 46477 | O22: Memadai | P22: Efektif | Q22: Manajemen siklus hidup akun pengguna, registrasi, penguncian lockout 5x gagal, dan deaktifasi. | R22: Pertahankan efektivitas kontrol dan lakukan review operasional berkala | S22: Sedang | T22: 46477 | U22: Dimas (Group Vision) | V22: 46302 | W22: =IF(G22="Belum ditentukan","Tentukan relevansi",IF(G22="Tidak berlaku",IF(OR(H22="",U22="",V22=""),"Lengkapi justifikasi","Tercatat"),IF(OR(J22="",L22="",N22="",O22="",P22=""),"Lengkapi assessment",IF(AND(I22="Diterapkan",J22="Lengkap",O22="Memadai",P22="Efektif",OR(K22="",U22="",V22="")),"Lengkapi bukti/reviewer","Tercatat")))) | X22: =IF(G22="Belum ditentukan","Belum dinilai",IF(G22="Tidak berlaku",IF(W22="Tercatat","Dikecualikan","Belum siap"),IF(AND(I22="Diterapkan",J22="Lengkap",O22="Memadai",P22="Efektif",W22="Tercatat"),"Siap","Belum siap"))) | Y22: =IF(G22="Belum ditentukan","Belum dijadwalkan",IF(N22="","Tanpa jadwal",IF(N22<'Master Data'!$C$9,"Review lewat","Dalam jadwal"))) | Z22: =IF(X22="Belum dinilai","Belum dinilai",IF(AND(OR(X22="Siap",X22="Dikecualikan"),Y22="Dalam jadwal"),"Tidak","Ya"))
B23: A.5.17 | C23: Organizational | D23: Informasi autentikasi | E23: Kredensial diterbitkan, disimpan, dan digunakan secara aman | F23: Password/MFA policy, konfigurasi, proses reset, sampel log | G23: Berlaku | H23: Kontrol A.5.17 relevan dan wajib diterapkan pada platform operasional auditsphere.app. | I23: Diterapkan | J23: Lengkap | K23: SRC-backend/auth-service/pkg/utils/password.go | L23: Lead Developer | M23: 46302 | N23: 46477 | O23: Memadai | P23: Efektif | Q23: Hashing kredensial menggunakan bcrypt dan perlindungan secret MFA TOTP di database terenkripsi. | R23: Pertahankan efektivitas kontrol dan lakukan review operasional berkala | S23: Sedang | T23: 46477 | U23: Dimas (Group Vision) | V23: 46302 | W23: =IF(G23="Belum ditentukan","Tentukan relevansi",IF(G23="Tidak berlaku",IF(OR(H23="",U23="",V23=""),"Lengkapi justifikasi","Tercatat"),IF(OR(J23="",L23="",N23="",O23="",P23=""),"Lengkapi assessment",IF(AND(I23="Diterapkan",J23="Lengkap",O23="Memadai",P23="Efektif",OR(K23="",U23="",V23="")),"Lengkapi bukti/reviewer","Tercatat")))) | X23: =IF(G23="Belum ditentukan","Belum dinilai",IF(G23="Tidak berlaku",IF(W23="Tercatat","Dikecualikan","Belum siap"),IF(AND(I23="Diterapkan",J23="Lengkap",O23="Memadai",P23="Efektif",W23="Tercatat"),"Siap","Belum siap"))) | Y23: =IF(G23="Belum ditentukan","Belum dijadwalkan",IF(N23="","Tanpa jadwal",IF(N23<'Master Data'!$C$9,"Review lewat","Dalam jadwal"))) | Z23: =IF(X23="Belum dinilai","Belum dinilai",IF(AND(OR(X23="Siap",X23="Dikecualikan"),Y23="Dalam jadwal"),"Tidak","Ya"))
B24: A.5.18 | C24: Organizational | D24: Hak akses | E24: Pemberian, perubahan, review, dan pencabutan akses dikendalikan | F24: Form akses, approval, recertification report, tiket pencabutan | G24: Berlaku | H24: Kontrol A.5.18 relevan dan wajib diterapkan pada platform operasional auditsphere.app. | I24: Diterapkan | J24: Lengkap | K24: SRC-backend/auth-service/controllers/auth | L24: Engineering Lead | M24: 46302 | N24: 46477 | O24: Memadai | P24: Efektif | Q24: Pemberian dan pencabutan hak akses terkelola terpusat dengan jadwal evaluasi berkala. | R24: Pertahankan efektivitas kontrol dan lakukan review operasional berkala | S24: Sedang | T24: 46477 | U24: Dimas (Group Vision) | V24: 46302 | W24: =IF(G24="Belum ditentukan","Tentukan relevansi",IF(G24="Tidak berlaku",IF(OR(H24="",U24="",V24=""),"Lengkapi justifikasi","Tercatat"),IF(OR(J24="",L24="",N24="",O24="",P24=""),"Lengkapi assessment",IF(AND(I24="Diterapkan",J24="Lengkap",O24="Memadai",P24="Efektif",OR(K24="",U24="",V24="")),"Lengkapi bukti/reviewer","Tercatat")))) | X24: =IF(G24="Belum ditentukan","Belum dinilai",IF(G24="Tidak berlaku",IF(W24="Tercatat","Dikecualikan","Belum siap"),IF(AND(I24="Diterapkan",J24="Lengkap",O24="Memadai",P24="Efektif",W24="Tercatat"),"Siap","Belum siap"))) | Y24: =IF(G24="Belum ditentukan","Belum dijadwalkan",IF(N24="","Tanpa jadwal",IF(N24<'Master Data'!$C$9,"Review lewat","Dalam jadwal"))) | Z24: =IF(X24="Belum dinilai","Belum dinilai",IF(AND(OR(X24="Siap",X24="Dikecualikan"),Y24="Dalam jadwal"),"Tidak","Ya"))
B25: A.5.19 | C25: Organizational | D25: Keamanan dalam hubungan pemasok | E25: Risiko keamanan pemasok dinilai dan dikelola | F25: Vendor risk assessment, klasifikasi vendor, due diligence | G25: Berlaku | H25: Kontrol A.5.19 relevan dan wajib diterapkan pada platform operasional auditsphere.app. | I25: Diterapkan | J25: Lengkap | K25: DOC-CPA-001_Cloud_Provider_Assessment | L25: DevOps Lead | M25: 46302 | N25: 46477 | O25: Memadai | P25: Efektif | Q25: Asesmen risiko penyedia cloud (CPA-001) dilakukan sebelum pengadaan infrastruktur. | R25: Pertahankan efektivitas kontrol dan lakukan review operasional berkala | S25: Sedang | T25: 46477 | U25: Dimas (Group Vision) | V25: 46302 | W25: =IF(G25="Belum ditentukan","Tentukan relevansi",IF(G25="Tidak berlaku",IF(OR(H25="",U25="",V25=""),"Lengkapi justifikasi","Tercatat"),IF(OR(J25="",L25="",N25="",O25="",P25=""),"Lengkapi assessment",IF(AND(I25="Diterapkan",J25="Lengkap",O25="Memadai",P25="Efektif",OR(K25="",U25="",V25="")),"Lengkapi bukti/reviewer","Tercatat")))) | X25: =IF(G25="Belum ditentukan","Belum dinilai",IF(G25="Tidak berlaku",IF(W25="Tercatat","Dikecualikan","Belum siap"),IF(AND(I25="Diterapkan",J25="Lengkap",O25="Memadai",P25="Efektif",W25="Tercatat"),"Siap","Belum siap"))) | Y25: =IF(G25="Belum ditentukan","Belum dijadwalkan",IF(N25="","Tanpa jadwal",IF(N25<'Master Data'!$C$9,"Review lewat","Dalam jadwal"))) | Z25: =IF(X25="Belum dinilai","Belum dinilai",IF(AND(OR(X25="Siap",X25="Dikecualikan"),Y25="Dalam jadwal"),"Tidak","Ya"))
B26: A.5.20 | C26: Organizational | D26: Keamanan dalam perjanjian pemasok | E26: Persyaratan keamanan dimasukkan ke kontrak pemasok | F26: Kontrak, SLA, DPA, security schedule, daftar klausul | G26: Berlaku | H26: Kontrol A.5.20 relevan dan wajib diterapkan pada platform operasional auditsphere.app. | I26: Diterapkan | J26: Lengkap | K26: DOC-CPA-001-DPA-Annex | L26: Legal Counsel | M26: 46302 | N26: 46477 | O26: Memadai | P26: Efektif | Q26: Perjanjian pemrosesan data (DPA) dan kepatuhan UU PDP No. 27/2022 tercantum dalam kontrak vendor. | R26: Pertahankan efektivitas kontrol dan lakukan review operasional berkala | S26: Sedang | T26: 46477 | U26: Dimas (Group Vision) | V26: 46302 | W26: =IF(G26="Belum ditentukan","Tentukan relevansi",IF(G26="Tidak berlaku",IF(OR(H26="",U26="",V26=""),"Lengkapi justifikasi","Tercatat"),IF(OR(J26="",L26="",N26="",O26="",P26=""),"Lengkapi assessment",IF(AND(I26="Diterapkan",J26="Lengkap",O26="Memadai",P26="Efektif",OR(K26="",U26="",V26="")),"Lengkapi bukti/reviewer","Tercatat")))) | X26: =IF(G26="Belum ditentukan","Belum dinilai",IF(G26="Tidak berlaku",IF(W26="Tercatat","Dikecualikan","Belum siap"),IF(AND(I26="Diterapkan",J26="Lengkap",O26="Memadai",P26="Efektif",W26="Tercatat"),"Siap","Belum siap"))) | Y26: =IF(G26="Belum ditentukan","Belum dijadwalkan",IF(N26="","Tanpa jadwal",IF(N26<'Master Data'!$C$9,"Review lewat","Dalam jadwal"))) | Z26: =IF(X26="Belum dinilai","Belum dinilai",IF(AND(OR(X26="Siap",X26="Dikecualikan"),Y26="Dalam jadwal"),"Tidak","Ya"))
B27: A.5.21 | C27: Organizational | D27: Keamanan rantai pasok TIK | E27: Risiko sepanjang rantai pasok produk dan layanan TIK dikendalikan | F27: Supply-chain assessment, SBOM, persyaratan subkontraktor | G27: Berlaku | H27: Mencegah dependensi berbahaya dan supply chain attack pada ekosistem pustaka open-source. | L27: DevOps Lead | M27: 46302 | N27: 46356 | Q27: Pipeline build belum dilengkapi scanner kerentanan dependensi otomatis (Trivy/Snyk) dan penandatanganan digital image kontainer (Cosign). | R27: Rekomendasi: Tambahkan langkah otomatisasi pada pipeline GitHub Actions untuk Trivy vulnerability scanning dan penandatanganan image kontainer menggunakan Cosign sebelum push ke VPS. | S27: Tinggi | T27: 46356 | W27: =IF(G27="Belum ditentukan","Tentukan relevansi",IF(G27="Tidak berlaku",IF(OR(H27="",U27="",V27=""),"Lengkapi justifikasi","Tercatat"),IF(OR(J27="",L27="",N27="",O27="",P27=""),"Lengkapi assessment",IF(AND(I27="Diterapkan",J27="Lengkap",O27="Memadai",P27="Efektif",OR(K27="",U27="",V27="")),"Lengkapi bukti/reviewer","Tercatat")))) | X27: =IF(G27="Belum ditentukan","Belum dinilai",IF(G27="Tidak berlaku",IF(W27="Tercatat","Dikecualikan","Belum siap"),IF(AND(I27="Diterapkan",J27="Lengkap",O27="Memadai",P27="Efektif",W27="Tercatat"),"Siap","Belum siap"))) | Y27: =IF(G27="Belum ditentukan","Belum dijadwalkan",IF(N27="","Tanpa jadwal",IF(N27<'Master Data'!$C$9,"Review lewat","Dalam jadwal"))) | Z27: =IF(X27="Belum dinilai","Belum dinilai",IF(AND(OR(X27="Siap",X27="Dikecualikan"),Y27="Dalam jadwal"),"Tidak","Ya"))
B28: A.5.22 | C28: Organizational | D28: Pemantauan dan perubahan layanan pemasok | E28: Kinerja, perubahan, dan kepatuhan pemasok direview | F28: SLA report, review meeting, change notice, action log | G28: Berlaku | H28: Kontrol A.5.22 relevan dan wajib diterapkan pada platform operasional auditsphere.app. | I28: Diterapkan | J28: Lengkap | K28: DOC-CPA-001-Sec6-Monitoring | L28: DevOps Lead | M28: 46302 | N28: 46477 | O28: Memadai | P28: Efektif | Q28: Pemantauan status operasional dan audit kepatuhan tahunan vendor cloud terjadwal resmi. | R28: Pertahankan efektivitas kontrol dan lakukan review operasional berkala | S28: Sedang | T28: 46477 | U28: Dimas (Group Vision) | V28: 46302 | W28: =IF(G28="Belum ditentukan","Tentukan relevansi",IF(G28="Tidak berlaku",IF(OR(H28="",U28="",V28=""),"Lengkapi justifikasi","Tercatat"),IF(OR(J28="",L28="",N28="",O28="",P28=""),"Lengkapi assessment",IF(AND(I28="Diterapkan",J28="Lengkap",O28="Memadai",P28="Efektif",OR(K28="",U28="",V28="")),"Lengkapi bukti/reviewer","Tercatat")))) | X28: =IF(G28="Belum ditentukan","Belum dinilai",IF(G28="Tidak berlaku",IF(W28="Tercatat","Dikecualikan","Belum siap"),IF(AND(I28="Diterapkan",J28="Lengkap",O28="Memadai",P28="Efektif",W28="Tercatat"),"Siap","Belum siap"))) | Y28: =IF(G28="Belum ditentukan","Belum dijadwalkan",IF(N28="","Tanpa jadwal",IF(N28<'Master Data'!$C$9,"Review lewat","Dalam jadwal"))) | Z28: =IF(X28="Belum dinilai","Belum dinilai",IF(AND(OR(X28="Siap",X28="Dikecualikan"),Y28="Dalam jadwal"),"Tidak","Ya"))
B29: A.5.23 | C29: Organizational | D29: Keamanan penggunaan layanan cloud | E29: Akuisisi, penggunaan, perubahan, dan exit cloud dikelola | F29: Cloud policy, CSP assessment, konfigurasi, exit plan | G29: Berlaku | H29: Kontrol A.5.23 relevan dan wajib diterapkan pada platform operasional auditsphere.app. | I29: Diterapkan | J29: Lengkap | K29: DOC-CSP-001_Cloud_Security_Policy | L29: DevOps Lead | M29: 46302 | N29: 46477 | O29: Memadai | P29: Efektif | Q29: Paket tata kelola cloud (CSP-001, CSRM-001, CPA-001, CES-001) telah disahkan dan diimplementasikan. | R29: Pertahankan efektivitas kontrol dan lakukan review operasional berkala | S29: Sedang | T29: 46477 | U29: Dimas (Group Vision) | V29: 46302 | W29: =IF(G29="Belum ditentukan","Tentukan relevansi",IF(G29="Tidak berlaku",IF(OR(H29="",U29="",V29=""),"Lengkapi justifikasi","Tercatat"),IF(OR(J29="",L29="",N29="",O29="",P29=""),"Lengkapi assessment",IF(AND(I29="Diterapkan",J29="Lengkap",O29="Memadai",P29="Efektif",OR(K29="",U29="",V29="")),"Lengkapi bukti/reviewer","Tercatat")))) | X29: =IF(G29="Belum ditentukan","Belum dinilai",IF(G29="Tidak berlaku",IF(W29="Tercatat","Dikecualikan","Belum siap"),IF(AND(I29="Diterapkan",J29="Lengkap",O29="Memadai",P29="Efektif",W29="Tercatat"),"Siap","Belum siap"))) | Y29: =IF(G29="Belum ditentukan","Belum dijadwalkan",IF(N29="","Tanpa jadwal",IF(N29<'Master Data'!$C$9,"Review lewat","Dalam jadwal"))) | Z29: =IF(X29="Belum dinilai","Belum dinilai",IF(AND(OR(X29="Siap",X29="Dikecualikan"),Y29="Dalam jadwal"),"Tidak","Ya"))
B30: A.5.24 | C30: Organizational | D30: Persiapan manajemen insiden | E30: Peran, proses, kanal, dan alat respons insiden siap digunakan | F30: IR plan, playbook, contact tree, hasil simulasi | G30: Berlaku | H30: Kontrol A.5.24 relevan dan wajib diterapkan pada platform operasional auditsphere.app. | I30: Diterapkan | J30: Lengkap | K30: DOC-ISO-AS-001-Sec11 | L30: Incident Response Lead | M30: 46302 | N30: 46477 | O30: Memadai | P30: Efektif | Q30: Tim respons insiden dan format pelaporan eskalasi Leadership OS AIFL disahkan. | R30: Pertahankan efektivitas kontrol dan lakukan review operasional berkala | S30: Sedang | T30: 46477 | U30: Dimas (Group Vision) | V30: 46302 | W30: =IF(G30="Belum ditentukan","Tentukan relevansi",IF(G30="Tidak berlaku",IF(OR(H30="",U30="",V30=""),"Lengkapi justifikasi","Tercatat"),IF(OR(J30="",L30="",N30="",O30="",P30=""),"Lengkapi assessment",IF(AND(I30="Diterapkan",J30="Lengkap",O30="Memadai",P30="Efektif",OR(K30="",U30="",V30="")),"Lengkapi bukti/reviewer","Tercatat")))) | X30: =IF(G30="Belum ditentukan","Belum dinilai",IF(G30="Tidak berlaku",IF(W30="Tercatat","Dikecualikan","Belum siap"),IF(AND(I30="Diterapkan",J30="Lengkap",O30="Memadai",P30="Efektif",W30="Tercatat"),"Siap","Belum siap"))) | Y30: =IF(G30="Belum ditentukan","Belum dijadwalkan",IF(N30="","Tanpa jadwal",IF(N30<'Master Data'!$C$9,"Review lewat","Dalam jadwal"))) | Z30: =IF(X30="Belum dinilai","Belum dinilai",IF(AND(OR(X30="Siap",X30="Dikecualikan"),Y30="Dalam jadwal"),"Tidak","Ya"))
B31: A.5.25 | C31: Organizational | D31: Penilaian kejadian keamanan | E31: Event dinilai konsisten untuk menentukan apakah menjadi insiden | F31: Kriteria klasifikasi, event ticket, decision log, SLA triage | G31: Berlaku | H31: Kontrol A.5.25 relevan dan wajib diterapkan pada platform operasional auditsphere.app. | I31: Diterapkan | J31: Lengkap | K31: DOC-ISO-AS-001-Sec11.3 | L31: SOC Lead | M31: 46302 | N31: 46477 | O31: Memadai | P31: Efektif | Q31: Klasifikasi tingkat keparahan insiden (Critical, Major, Minor) dengan target SLA respons terukur. | R31: Pertahankan efektivitas kontrol dan lakukan review operasional berkala | S31: Sedang | T31: 46477 | U31: Dimas (Group Vision) | V31: 46302 | W31: =IF(G31="Belum ditentukan","Tentukan relevansi",IF(G31="Tidak berlaku",IF(OR(H31="",U31="",V31=""),"Lengkapi justifikasi","Tercatat"),IF(OR(J31="",L31="",N31="",O31="",P31=""),"Lengkapi assessment",IF(AND(I31="Diterapkan",J31="Lengkap",O31="Memadai",P31="Efektif",OR(K31="",U31="",V31="")),"Lengkapi bukti/reviewer","Tercatat")))) | X31: =IF(G31="Belum ditentukan","Belum dinilai",IF(G31="Tidak berlaku",IF(W31="Tercatat","Dikecualikan","Belum siap"),IF(AND(I31="Diterapkan",J31="Lengkap",O31="Memadai",P31="Efektif",W31="Tercatat"),"Siap","Belum siap"))) | Y31: =IF(G31="Belum ditentukan","Belum dijadwalkan",IF(N31="","Tanpa jadwal",IF(N31<'Master Data'!$C$9,"Review lewat","Dalam jadwal"))) | Z31: =IF(X31="Belum dinilai","Belum dinilai",IF(AND(OR(X31="Siap",X31="Dikecualikan"),Y31="Dalam jadwal"),"Tidak","Ya"))
B32: A.5.26 | C32: Organizational | D32: Respons insiden keamanan | E32: Insiden ditangani sesuai prosedur dan kewenangan | F32: Incident record, timeline, containment log, komunikasi | G32: Berlaku | H32: Kontrol A.5.26 relevan dan wajib diterapkan pada platform operasional auditsphere.app. | I32: Diterapkan | J32: Lengkap | K32: DOC-ISO-AS-001-Sec11.1 | L32: SOC Lead | M32: 46302 | N32: 46477 | O32: Memadai | P32: Efektif | Q32: Prosedur penahanan insiden, isolasi container, dan revocations kredensial terstandarisasi. | R32: Pertahankan efektivitas kontrol dan lakukan review operasional berkala | S32: Sedang | T32: 46477 | U32: Dimas (Group Vision) | V32: 46302 | W32: =IF(G32="Belum ditentukan","Tentukan relevansi",IF(G32="Tidak berlaku",IF(OR(H32="",U32="",V32=""),"Lengkapi justifikasi","Tercatat"),IF(OR(J32="",L32="",N32="",O32="",P32=""),"Lengkapi assessment",IF(AND(I32="Diterapkan",J32="Lengkap",O32="Memadai",P32="Efektif",OR(K32="",U32="",V32="")),"Lengkapi bukti/reviewer","Tercatat")))) | X32: =IF(G32="Belum ditentukan","Belum dinilai",IF(G32="Tidak berlaku",IF(W32="Tercatat","Dikecualikan","Belum siap"),IF(AND(I32="Diterapkan",J32="Lengkap",O32="Memadai",P32="Efektif",W32="Tercatat"),"Siap","Belum siap"))) | Y32: =IF(G32="Belum ditentukan","Belum dijadwalkan",IF(N32="","Tanpa jadwal",IF(N32<'Master Data'!$C$9,"Review lewat","Dalam jadwal"))) | Z32: =IF(X32="Belum dinilai","Belum dinilai",IF(AND(OR(X32="Siap",X32="Dikecualikan"),Y32="Dalam jadwal"),"Tidak","Ya"))
B33: A.5.27 | C33: Organizational | D33: Pembelajaran dari insiden | E33: Akar masalah dan pembelajaran diterapkan untuk mencegah pengulangan | F33: Post-incident review, RCA, improvement ticket, lesson learned | G33: Berlaku | H33: Mencegah insiden berulang melalui analisis akar masalah (Root Cause Analysis). | L33: Security Officer | M33: 46302 | N33: 46387 | Q33: Template database Post-Incident Review (PIR) dan penelusuran tindakan korektif pasca-insiden belum dioperasikan secara sistematis. | R33: Rekomendasi: Buat formulir baku PIR (Post-Incident Review) yang mencakup 5-Whys RCA, timeline kejadian, serta pelacakan remediasi ke backlog rekayasa. | S33: Sedang | T33: 46387 | W33: =IF(G33="Belum ditentukan","Tentukan relevansi",IF(G33="Tidak berlaku",IF(OR(H33="",U33="",V33=""),"Lengkapi justifikasi","Tercatat"),IF(OR(J33="",L33="",N33="",O33="",P33=""),"Lengkapi assessment",IF(AND(I33="Diterapkan",J33="Lengkap",O33="Memadai",P33="Efektif",OR(K33="",U33="",V33="")),"Lengkapi bukti/reviewer","Tercatat")))) | X33: =IF(G33="Belum ditentukan","Belum dinilai",IF(G33="Tidak berlaku",IF(W33="Tercatat","Dikecualikan","Belum siap"),IF(AND(I33="Diterapkan",J33="Lengkap",O33="Memadai",P33="Efektif",W33="Tercatat"),"Siap","Belum siap"))) | Y33: =IF(G33="Belum ditentukan","Belum dijadwalkan",IF(N33="","Tanpa jadwal",IF(N33<'Master Data'!$C$9,"Review lewat","Dalam jadwal"))) | Z33: =IF(X33="Belum dinilai","Belum dinilai",IF(AND(OR(X33="Siap",X33="Dikecualikan"),Y33="Dalam jadwal"),"Tidak","Ya"))
B34: A.5.28 | C34: Organizational | D34: Pengumpulan bukti | E34: Bukti insiden dikumpulkan dan dijaga integritas serta chain of custody | F34: Prosedur forensik, evidence log, hash, chain-of-custody form | G34: Berlaku | H34: Kontrol A.5.28 relevan dan wajib diterapkan pada platform operasional auditsphere.app. | I34: Diterapkan | J34: Lengkap | K34: DOC-FRP-001_Forensic_Readiness | L34: Security Officer | M34: 46302 | N34: 46477 | O34: Memadai | P34: Efektif | Q34: Prosedur kesiapan forensik digital dan pemeliharaan rantai keaslian bukti (FRP-001) disahkan. | R34: Pertahankan efektivitas kontrol dan lakukan review operasional berkala | S34: Sedang | T34: 46477 | U34: Dimas (Group Vision) | V34: 46302 | W34: =IF(G34="Belum ditentukan","Tentukan relevansi",IF(G34="Tidak berlaku",IF(OR(H34="",U34="",V34=""),"Lengkapi justifikasi","Tercatat"),IF(OR(J34="",L34="",N34="",O34="",P34=""),"Lengkapi assessment",IF(AND(I34="Diterapkan",J34="Lengkap",O34="Memadai",P34="Efektif",OR(K34="",U34="",V34="")),"Lengkapi bukti/reviewer","Tercatat")))) | X34: =IF(G34="Belum ditentukan","Belum dinilai",IF(G34="Tidak berlaku",IF(W34="Tercatat","Dikecualikan","Belum siap"),IF(AND(I34="Diterapkan",J34="Lengkap",O34="Memadai",P34="Efektif",W34="Tercatat"),"Siap","Belum siap"))) | Y34: =IF(G34="Belum ditentukan","Belum dijadwalkan",IF(N34="","Tanpa jadwal",IF(N34<'Master Data'!$C$9,"Review lewat","Dalam jadwal"))) | Z34: =IF(X34="Belum dinilai","Belum dinilai",IF(AND(OR(X34="Siap",X34="Dikecualikan"),Y34="Dalam jadwal"),"Tidak","Ya"))
B35: A.5.29 | C35: Organizational | D35: Keamanan selama gangguan | E35: Keamanan informasi dipertahankan pada kondisi gangguan | F35: BCP, prosedur mode darurat, hasil latihan, risk acceptance | G35: Berlaku | H35: Kontrol A.5.29 relevan dan wajib diterapkan pada platform operasional auditsphere.app. | I35: Diterapkan | J35: Lengkap | K35: DOC-ISO-AS-001-Sec12 | L35: Infrastructure Lead | M35: 46302 | N35: 46477 | O35: Memadai | P35: Efektif | Q35: Service backend stateless dirancang dapat di-deploy ulang cepat saat terjadi insiden. | R35: Pertahankan efektivitas kontrol dan lakukan review operasional berkala | S35: Sedang | T35: 46477 | U35: Dimas (Group Vision) | V35: 46302 | W35: =IF(G35="Belum ditentukan","Tentukan relevansi",IF(G35="Tidak berlaku",IF(OR(H35="",U35="",V35=""),"Lengkapi justifikasi","Tercatat"),IF(OR(J35="",L35="",N35="",O35="",P35=""),"Lengkapi assessment",IF(AND(I35="Diterapkan",J35="Lengkap",O35="Memadai",P35="Efektif",OR(K35="",U35="",V35="")),"Lengkapi bukti/reviewer","Tercatat")))) | X35: =IF(G35="Belum ditentukan","Belum dinilai",IF(G35="Tidak berlaku",IF(W35="Tercatat","Dikecualikan","Belum siap"),IF(AND(I35="Diterapkan",J35="Lengkap",O35="Memadai",P35="Efektif",W35="Tercatat"),"Siap","Belum siap"))) | Y35: =IF(G35="Belum ditentukan","Belum dijadwalkan",IF(N35="","Tanpa jadwal",IF(N35<'Master Data'!$C$9,"Review lewat","Dalam jadwal"))) | Z35: =IF(X35="Belum dinilai","Belum dinilai",IF(AND(OR(X35="Siap",X35="Dikecualikan"),Y35="Dalam jadwal"),"Tidak","Ya"))
B36: A.5.30 | C36: Organizational | D36: Kesiapan TIK untuk kelangsungan bisnis | E36: Kemampuan TIK mendukung target pemulihan yang disepakati | F36: DRP, BIA, RTO/RPO, hasil restore dan DR test | G36: Berlaku | H36: Kontrol A.5.30 relevan dan wajib diterapkan pada platform operasional auditsphere.app. | I36: Diterapkan | J36: Lengkap | K36: DOC-ISO-AS-001-Sec12.1 | L36: DevOps Lead | M36: 46302 | N36: 46477 | O36: Memadai | P36: Efektif | Q36: Target RTO (<1 jam) dan RPO (<15 menit) ditetapkan dan didukung pencadangan snapshot teratur. | R36: Pertahankan efektivitas kontrol dan lakukan review operasional berkala | S36: Sedang | T36: 46477 | U36: Dimas (Group Vision) | V36: 46302 | W36: =IF(G36="Belum ditentukan","Tentukan relevansi",IF(G36="Tidak berlaku",IF(OR(H36="",U36="",V36=""),"Lengkapi justifikasi","Tercatat"),IF(OR(J36="",L36="",N36="",O36="",P36=""),"Lengkapi assessment",IF(AND(I36="Diterapkan",J36="Lengkap",O36="Memadai",P36="Efektif",OR(K36="",U36="",V36="")),"Lengkapi bukti/reviewer","Tercatat")))) | X36: =IF(G36="Belum ditentukan","Belum dinilai",IF(G36="Tidak berlaku",IF(W36="Tercatat","Dikecualikan","Belum siap"),IF(AND(I36="Diterapkan",J36="Lengkap",O36="Memadai",P36="Efektif",W36="Tercatat"),"Siap","Belum siap"))) | Y36: =IF(G36="Belum ditentukan","Belum dijadwalkan",IF(N36="","Tanpa jadwal",IF(N36<'Master Data'!$C$9,"Review lewat","Dalam jadwal"))) | Z36: =IF(X36="Belum dinilai","Belum dinilai",IF(AND(OR(X36="Siap",X36="Dikecualikan"),Y36="Dalam jadwal"),"Tidak","Ya"))
B37: A.5.31 | C37: Organizational | D37: Persyaratan hukum dan kontraktual | E37: Kewajiban keamanan diidentifikasi, diperbarui, dan dipatuhi | F37: Legal register, compliance mapping, review regulasi, kontrak | G37: Berlaku | H37: Kontrol A.5.31 relevan dan wajib diterapkan pada platform operasional auditsphere.app. | I37: Diterapkan | J37: Lengkap | K37: DOC-ISO-AS-001-Sec3 | L37: Compliance Lead | M37: 46302 | N37: 46477 | O37: Memadai | P37: Efektif | Q37: Pemenuhan regulasi UU PDP No. 27/2022, UU ITE, dan standar IIA IPPF / ISACA ITAF terdokumentasi. | R37: Pertahankan efektivitas kontrol dan lakukan review operasional berkala | S37: Sedang | T37: 46477 | U37: Dimas (Group Vision) | V37: 46302 | W37: =IF(G37="Belum ditentukan","Tentukan relevansi",IF(G37="Tidak berlaku",IF(OR(H37="",U37="",V37=""),"Lengkapi justifikasi","Tercatat"),IF(OR(J37="",L37="",N37="",O37="",P37=""),"Lengkapi assessment",IF(AND(I37="Diterapkan",J37="Lengkap",O37="Memadai",P37="Efektif",OR(K37="",U37="",V37="")),"Lengkapi bukti/reviewer","Tercatat")))) | X37: =IF(G37="Belum ditentukan","Belum dinilai",IF(G37="Tidak berlaku",IF(W37="Tercatat","Dikecualikan","Belum siap"),IF(AND(I37="Diterapkan",J37="Lengkap",O37="Memadai",P37="Efektif",W37="Tercatat"),"Siap","Belum siap"))) | Y37: =IF(G37="Belum ditentukan","Belum dijadwalkan",IF(N37="","Tanpa jadwal",IF(N37<'Master Data'!$C$9,"Review lewat","Dalam jadwal"))) | Z37: =IF(X37="Belum dinilai","Belum dinilai",IF(AND(OR(X37="Siap",X37="Dikecualikan"),Y37="Dalam jadwal"),"Tidak","Ya"))
B38: A.5.32 | C38: Organizational | D38: Hak kekayaan intelektual | E38: Penggunaan perangkat lunak dan konten mematuhi hak kekayaan intelektual | F38: License register, bukti pembelian, software inventory, audit lisensi | G38: Berlaku | H38: Kontrol A.5.32 relevan dan wajib diterapkan pada platform operasional auditsphere.app. | I38: Diterapkan | J38: Lengkap | K38: SRC-backend/python-ai/requirements.txt | L38: Tech Lead AIFL | M38: 46302 | N38: 46477 | O38: Memadai | P38: Efektif | Q38: Audit lisensi pustaka open-source diverifikasi legalitas komersialnya (MIT, BSD, Apache 2.0). | R38: Pertahankan efektivitas kontrol dan lakukan review operasional berkala | S38: Sedang | T38: 46477 | U38: Dimas (Group Vision) | V38: 46302 | W38: =IF(G38="Belum ditentukan","Tentukan relevansi",IF(G38="Tidak berlaku",IF(OR(H38="",U38="",V38=""),"Lengkapi justifikasi","Tercatat"),IF(OR(J38="",L38="",N38="",O38="",P38=""),"Lengkapi assessment",IF(AND(I38="Diterapkan",J38="Lengkap",O38="Memadai",P38="Efektif",OR(K38="",U38="",V38="")),"Lengkapi bukti/reviewer","Tercatat")))) | X38: =IF(G38="Belum ditentukan","Belum dinilai",IF(G38="Tidak berlaku",IF(W38="Tercatat","Dikecualikan","Belum siap"),IF(AND(I38="Diterapkan",J38="Lengkap",O38="Memadai",P38="Efektif",W38="Tercatat"),"Siap","Belum siap"))) | Y38: =IF(G38="Belum ditentukan","Belum dijadwalkan",IF(N38="","Tanpa jadwal",IF(N38<'Master Data'!$C$9,"Review lewat","Dalam jadwal"))) | Z38: =IF(X38="Belum dinilai","Belum dinilai",IF(AND(OR(X38="Siap",X38="Dikecualikan"),Y38="Dalam jadwal"),"Tidak","Ya"))
B39: A.5.33 | C39: Organizational | D39: Perlindungan rekaman | E39: Rekaman dilindungi sesuai kebutuhan retensi dan integritas | F39: Retention schedule, access log, backup, disposal record | G39: Berlaku | H39: Kontrol A.5.33 relevan dan wajib diterapkan pada platform operasional auditsphere.app. | I39: Diterapkan | J39: Lengkap | K39: SRC-backend/auth-service/pkg/kafka | L39: Engineering Lead | M39: 46302 | N39: 46477 | O39: Memadai | P39: Efektif | Q39: Log audit trail disimpan immutable dengan hashing SHA-256 dan retensi data minimal 5 tahun. | R39: Pertahankan efektivitas kontrol dan lakukan review operasional berkala | S39: Sedang | T39: 46477 | U39: Dimas (Group Vision) | V39: 46302 | W39: =IF(G39="Belum ditentukan","Tentukan relevansi",IF(G39="Tidak berlaku",IF(OR(H39="",U39="",V39=""),"Lengkapi justifikasi","Tercatat"),IF(OR(J39="",L39="",N39="",O39="",P39=""),"Lengkapi assessment",IF(AND(I39="Diterapkan",J39="Lengkap",O39="Memadai",P39="Efektif",OR(K39="",U39="",V39="")),"Lengkapi bukti/reviewer","Tercatat")))) | X39: =IF(G39="Belum ditentukan","Belum dinilai",IF(G39="Tidak berlaku",IF(W39="Tercatat","Dikecualikan","Belum siap"),IF(AND(I39="Diterapkan",J39="Lengkap",O39="Memadai",P39="Efektif",W39="Tercatat"),"Siap","Belum siap"))) | Y39: =IF(G39="Belum ditentukan","Belum dijadwalkan",IF(N39="","Tanpa jadwal",IF(N39<'Master Data'!$C$9,"Review lewat","Dalam jadwal"))) | Z39: =IF(X39="Belum dinilai","Belum dinilai",IF(AND(OR(X39="Siap",X39="Dikecualikan"),Y39="Dalam jadwal"),"Tidak","Ya"))
B40: A.5.34 | C40: Organizational | D40: Privasi dan perlindungan PII | E40: PII diproses sesuai kewajiban dan kontrol privasi | F40: Data inventory, privacy notice, DPIA, consent, DPA | G40: Berlaku | H40: Kontrol A.5.34 relevan dan wajib diterapkan pada platform operasional auditsphere.app. | I40: Diterapkan | J40: Lengkap | K40: DOC-ISO-AS-001-Sec13.3 | L40: Data Protection Officer | M40: 46302 | N40: 46477 | O40: Memadai | P40: Efektif | Q40: Residensi data lokal di wilayah hukum Indonesia (VPS IP 202.10.34.166 / Region Jakarta) dipatuhi. | R40: Pertahankan efektivitas kontrol dan lakukan review operasional berkala | S40: Sedang | T40: 46477 | U40: Dimas (Group Vision) | V40: 46302 | W40: =IF(G40="Belum ditentukan","Tentukan relevansi",IF(G40="Tidak berlaku",IF(OR(H40="",U40="",V40=""),"Lengkapi justifikasi","Tercatat"),IF(OR(J40="",L40="",N40="",O40="",P40=""),"Lengkapi assessment",IF(AND(I40="Diterapkan",J40="Lengkap",O40="Memadai",P40="Efektif",OR(K40="",U40="",V40="")),"Lengkapi bukti/reviewer","Tercatat")))) | X40: =IF(G40="Belum ditentukan","Belum dinilai",IF(G40="Tidak berlaku",IF(W40="Tercatat","Dikecualikan","Belum siap"),IF(AND(I40="Diterapkan",J40="Lengkap",O40="Memadai",P40="Efektif",W40="Tercatat"),"Siap","Belum siap"))) | Y40: =IF(G40="Belum ditentukan","Belum dijadwalkan",IF(N40="","Tanpa jadwal",IF(N40<'Master Data'!$C$9,"Review lewat","Dalam jadwal"))) | Z40: =IF(X40="Belum dinilai","Belum dinilai",IF(AND(OR(X40="Siap",X40="Dikecualikan"),Y40="Dalam jadwal"),"Tidak","Ya"))
B41: A.5.35 | C41: Organizational | D41: Tinjauan independen keamanan informasi | E41: Tinjauan independen dilakukan terencana atau setelah perubahan besar | F41: Audit plan, laporan review, independensi auditor, action log | G41: Berlaku | H41: Memastikan objektivitas keselarasan ISMS melalui penilaian independen pihak ketiga. | L41: Lead Information Security | M41: 46302 | N41: 46446 | Q41: Audit independen eksternal formal ISO/IEC 27001 belum pernah dilaksanakan pada siklus berjalan. | R41: Rekomendasi: Jadwalkan pre-assessment audit independen bersama badan sertifikasi terakreditasi KAN menjelang audit tahap 1 formal. | S41: Tinggi | T41: 46446 | W41: =IF(G41="Belum ditentukan","Tentukan relevansi",IF(G41="Tidak berlaku",IF(OR(H41="",U41="",V41=""),"Lengkapi justifikasi","Tercatat"),IF(OR(J41="",L41="",N41="",O41="",P41=""),"Lengkapi assessment",IF(AND(I41="Diterapkan",J41="Lengkap",O41="Memadai",P41="Efektif",OR(K41="",U41="",V41="")),"Lengkapi bukti/reviewer","Tercatat")))) | X41: =IF(G41="Belum ditentukan","Belum dinilai",IF(G41="Tidak berlaku",IF(W41="Tercatat","Dikecualikan","Belum siap"),IF(AND(I41="Diterapkan",J41="Lengkap",O41="Memadai",P41="Efektif",W41="Tercatat"),"Siap","Belum siap"))) | Y41: =IF(G41="Belum ditentukan","Belum dijadwalkan",IF(N41="","Tanpa jadwal",IF(N41<'Master Data'!$C$9,"Review lewat","Dalam jadwal"))) | Z41: =IF(X41="Belum dinilai","Belum dinilai",IF(AND(OR(X41="Siap",X41="Dikecualikan"),Y41="Dalam jadwal"),"Tidak","Ya"))
